<mujoco model="dual_franka_panda_cable_sim">
<compiler angle="radian" meshdir="assets" autolimits="true"/>
<statistic center="0.3 0 0.4" extent="1"/>
<option integrator="implicit" timestep="1e-3" noslip_iterations="20"/>
    
<visual>
    <headlight diffuse="0.6 0.6 0.6" ambient="0.3 0.3 0.3" specular="0 0 0"/>
    <rgba haze="0.15 0.25 0.35 1"/>
    <global azimuth="120" elevation="-30"/>
</visual>

<!-- PANDA01 DEFAULTS -->
<default>
    <default class="panda_01">
        <material specular="0.5" shininess="0.25"/>
        <joint armature="0.1" damping="1" axis="0 0 1" range="-2.8973 2.8973"/>
        <general dyntype="none" biastype="affine" ctrlrange="-2.8973 2.8973" forcerange="-87 87"/>
        <default class="finger_01">
            <joint axis="0 1 0" type="slide" range="0 0.04"/>
        </default>
        <default class="visual_01">
            <geom type="mesh" contype="0" conaffinity="0" group="2"/>
        </default>
        <default class="collision_01">
            <geom type="mesh" group="3"/>
            <default class="fingertip_pad_collision_1_01">
                <geom type="box" size="0.0085 0.004 0.0085" pos="0 0.0055 0.0445"/>
            </default>
            <default class="fingertip_pad_collision_2_01">
                <geom type="box" size="0.003 0.002 0.003" pos="0.0055 0.002 0.05"/>
            </default>
            <default class="fingertip_pad_collision_3_01">
                <geom type="box" size="0.003 0.002 0.003" pos="-0.0055 0.002 0.05"/>
            </default>
            <default class="fingertip_pad_collision_4_01">
                <geom type="box" size="0.003 0.002 0.0035" pos="0.0055 0.002 0.0395"/>
            </default>
            <default class="fingertip_pad_collision_5_01">
                <geom type="box" size="0.003 0.002 0.0035" pos="-0.0055 0.002 0.0395"/>
            </default>
        </default>
    </default>
</default>

<!-- PANDA02 DEFAULTS -->
<default>
    <default class="panda_02">
        <material specular="0.5" shininess="0.25"/>
        <joint armature="0.1" damping="1" axis="0 0 1" range="-2.8973 2.8973"/>
        <general dyntype="none" biastype="affine" ctrlrange="-2.8973 2.8973" forcerange="-87 87"/>
        <default class="finger_02">
            <joint axis="0 1 0" type="slide" range="0 0.04"/>
        </default>
        <default class="visual_02">
            <geom type="mesh" contype="0" conaffinity="0" group="2"/>
        </default>
        <default class="collision_02">
            <geom type="mesh" group="3"/>
            <default class="fingertip_pad_collision_1_02">
                <geom type="box" size="0.0085 0.004 0.0085" pos="0 0.0055 0.0445"/>
            </default>
            <default class="fingertip_pad_collision_2_02">
                <geom type="box" size="0.003 0.002 0.003" pos="0.0055 0.002 0.05"/>
            </default>
            <default class="fingertip_pad_collision_3_02">
                <geom type="box" size="0.003 0.002 0.003" pos="-0.0055 0.002 0.05"/>
            </default>
            <default class="fingertip_pad_collision_4_02">
                <geom type="box" size="0.003 0.002 0.0035" pos="0.0055 0.002 0.0395"/>
            </default>
            <default class="fingertip_pad_collision_5_02">
                <geom type="box" size="0.003 0.002 0.0035" pos="-0.0055 0.002 0.0395"/>
            </default>
        </default>
    </default>
</default>

<asset>
    <!-- SCENE ASSETS -->
    <texture type="skybox" builtin="gradient" rgb1="0.3 0.5 0.7" rgb2="0 0 0" width="512" height="3072"/>
    <texture type="2d" name="groundplane" builtin="checker" mark="edge" rgb1="0.2 0.3 0.4" rgb2="0.1 0.2 0.3" markrgb="0.8 0.8 0.8" width="300" height="300"/>
    <material name="highlight_green" rgba="0 1 0 1" specular="0.5" shininess="1"/>
    <material name="groundplane" texture="groundplane" texuniform="true" texrepeat="5 5" reflectance="0.2"/>

    <!-- PANDA01 ASSETS -->
    <material class="panda_01" name="white_01" rgba="1 1 1 1"/>
    <material class="panda_01" name="off_white_01" rgba="0.901961 0.921569 0.929412 1"/>
    <material class="panda_01" name="black_01" rgba="0.25 0.25 0.25 1"/>
    <material class="panda_01" name="green_01" rgba="0 1 0 1"/>
    <material class="panda_01" name="light_blue_01" rgba="0.039216 0.541176 0.780392 1"/>
    
    <!-- collision meshes -->
    <mesh name="link0_c_01" file="link0_01.stl"/>
    <mesh name="link1_c_01" file="link1_01.stl"/>
    <mesh name="link2_c_01" file="link2_01.stl"/>
    <mesh name="link3_c_01" file="link3_01.stl"/>
    <mesh name="link4_c_01" file="link4_01.stl"/>
    <mesh name="link5_c0_01" file="link5_collision_0_01.obj"/>
    <mesh name="link5_c1_01" file="link5_collision_1_01.obj"/>
    <mesh name="link5_c2_01" file="link5_collision_2_01.obj"/>
    <mesh name="link6_c_01" file="link6_01.stl"/>
    <mesh name="link7_c_01" file="link7_01.stl"/>
    <mesh name="hand_c_01" file="hand_01.stl"/>

    <!-- visual meshes -->
    <mesh file="link0_0_01.obj"/>
    <mesh file="link0_1_01.obj"/>
    <mesh file="link0_2_01.obj"/>
    <mesh file="link0_3_01.obj"/>
    <mesh file="link0_4_01.obj"/>
    <mesh file="link0_5_01.obj"/>
    <mesh file="link0_7_01.obj"/>
    <mesh file="link0_8_01.obj"/>
    <mesh file="link0_9_01.obj"/>
    <mesh file="link0_10_01.obj"/>
    <mesh file="link0_11_01.obj"/>
    <mesh file="link1_01.obj"/>
    <mesh file="link2_01.obj"/>
    <mesh file="link3_0_01.obj"/>
    <mesh file="link3_1_01.obj"/>
    <mesh file="link3_2_01.obj"/>
    <mesh file="link3_3_01.obj"/>
    <mesh file="link4_0_01.obj"/>
    <mesh file="link4_1_01.obj"/>
    <mesh file="link4_2_01.obj"/>
    <mesh file="link4_3_01.obj"/>
    <mesh file="link5_0_01.obj"/>
    <mesh file="link5_1_01.obj"/>
    <mesh file="link5_2_01.obj"/>
    <mesh file="link6_0_01.obj"/>
    <mesh file="link6_1_01.obj"/>
    <mesh file="link6_2_01.obj"/>
    <mesh file="link6_3_01.obj"/>
    <mesh file="link6_4_01.obj"/>
    <mesh file="link6_5_01.obj"/>
    <mesh file="link6_6_01.obj"/>
    <mesh file="link6_7_01.obj"/>
    <mesh file="link6_8_01.obj"/>
    <mesh file="link6_9_01.obj"/>
    <mesh file="link6_10_01.obj"/>
    <mesh file="link6_11_01.obj"/>
    <mesh file="link6_12_01.obj"/>
    <mesh file="link6_13_01.obj"/>
    <mesh file="link6_14_01.obj"/>
    <mesh file="link6_15_01.obj"/>
    <mesh file="link6_16_01.obj"/>
    <mesh file="link7_0_01.obj"/>
    <mesh file="link7_1_01.obj"/>
    <mesh file="link7_2_01.obj"/>
    <mesh file="link7_3_01.obj"/>
    <mesh file="link7_4_01.obj"/>
    <mesh file="link7_5_01.obj"/>
    <mesh file="link7_6_01.obj"/>
    <mesh file="link7_7_01.obj"/>
    <mesh file="hand_0_01.obj"/>
    <mesh file="hand_1_01.obj"/>
    <mesh file="hand_2_01.obj"/>
    <mesh file="hand_3_01.obj"/>
    <mesh file="hand_4_01.obj"/>
    <mesh file="finger_0_01.obj"/>
    <mesh file="finger_1_01.obj"/>

    <!-- PANDA02 ASSETS -->
        <material class="panda_02" name="white_02" rgba="1 1 1 1"/>
    <material class="panda_02" name="off_white_02" rgba="0.901961 0.921569 0.929412 1"/>
    <material class="panda_02" name="black_02" rgba="0.25 0.25 0.25 1"/>
    <material class="panda_02" name="green_02" rgba="0 1 0 1"/>
    <material class="panda_02" name="light_blue_02" rgba="0.039216 0.541176 0.780392 1"/>

    <!-- collision meshes -->
    <mesh name="link0_c_02" file="link0_02.stl"/>
    <mesh name="link1_c_02" file="link1_02.stl"/>
    <mesh name="link2_c_02" file="link2_02.stl"/>
    <mesh name="link3_c_02" file="link3_02.stl"/>
    <mesh name="link4_c_02" file="link4_02.stl"/>
    <mesh name="link5_c0_02" file="link5_collision_0_02.obj"/>
    <mesh name="link5_c1_02" file="link5_collision_1_02.obj"/>
    <mesh name="link5_c2_02" file="link5_collision_2_02.obj"/>
    <mesh name="link6_c_02" file="link6_02.stl"/>
    <mesh name="link7_c_02" file="link7_02.stl"/>
    <mesh name="hand_c_02" file="hand_02.stl"/>

    <!-- visual meshes -->
    <mesh file="link0_0_02.obj"/>
    <mesh file="link0_1_02.obj"/>
    <mesh file="link0_2_02.obj"/>
    <mesh file="link0_3_02.obj"/>
    <mesh file="link0_4_02.obj"/>
    <mesh file="link0_5_02.obj"/>
    <mesh file="link0_7_02.obj"/>
    <mesh file="link0_8_02.obj"/>
    <mesh file="link0_9_02.obj"/>
    <mesh file="link0_10_02.obj"/>
    <mesh file="link0_11_02.obj"/>
    <mesh file="link1_02.obj"/>
    <mesh file="link2_02.obj"/>
    <mesh file="link3_0_02.obj"/>
    <mesh file="link3_1_02.obj"/>
    <mesh file="link3_2_02.obj"/>
    <mesh file="link3_3_02.obj"/>
    <mesh file="link4_0_02.obj"/>
    <mesh file="link4_1_02.obj"/>
    <mesh file="link4_2_02.obj"/>
    <mesh file="link4_3_02.obj"/>
    <mesh file="link5_0_02.obj"/>
    <mesh file="link5_1_02.obj"/>
    <mesh file="link5_2_02.obj"/>
    <mesh file="link6_0_02.obj"/>
    <mesh file="link6_1_02.obj"/>
    <mesh file="link6_2_02.obj"/>
    <mesh file="link6_3_02.obj"/>
    <mesh file="link6_4_02.obj"/>
    <mesh file="link6_5_02.obj"/>
    <mesh file="link6_6_02.obj"/>
    <mesh file="link6_7_02.obj"/>
    <mesh file="link6_8_02.obj"/>
    <mesh file="link6_9_02.obj"/>
    <mesh file="link6_10_02.obj"/>
    <mesh file="link6_11_02.obj"/>
    <mesh file="link6_12_02.obj"/>
    <mesh file="link6_13_02.obj"/>
    <mesh file="link6_14_02.obj"/>
    <mesh file="link6_15_02.obj"/>
    <mesh file="link6_16_02.obj"/>
    <mesh file="link7_0_02.obj"/>
    <mesh file="link7_1_02.obj"/>
    <mesh file="link7_2_02.obj"/>
    <mesh file="link7_3_02.obj"/>
    <mesh file="link7_4_02.obj"/>
    <mesh file="link7_5_02.obj"/>
    <mesh file="link7_6_02.obj"/>
    <mesh file="link7_7_02.obj"/>
    <mesh file="hand_0_02.obj"/>
    <mesh file="hand_1_02.obj"/>
    <mesh file="hand_2_02.obj"/>
    <mesh file="hand_3_02.obj"/>
    <mesh file="hand_4_02.obj"/>
    <mesh file="finger_0_02.obj"/>
    <mesh file="finger_1_02.obj"/>
</asset>

<worldbody>
<!-- TARGETS -->
<body name="target4" pos="-0.5 0 0.8">
    <joint name="target4_free" type="free" damping="0"/>
    <geom type="sphere" size="0.02" rgba="1 0 0 1" contype="0" conaffinity="0"/>
    <inertial pos="0 0 0" mass="1e-12" diaginertia="1e-12 1e-12 1e-12"/>
</body>
<body name="target5" pos="0 0.5 0.9">
    <joint name="target5_free" type="free" damping="0"/>
    <geom type="sphere" size="0.02" rgba="0 1 0 1" contype="0" conaffinity="0"/>
    <inertial pos="0 0 0" mass="1e-12" diaginertia="1e-12 1e-12 1e-12"/>
</body>
<body name="target6" pos="0.5 0 1.0">
    <joint name="target6_free" type="free" damping="0"/>
    <geom type="sphere" size="0.02" rgba="0.6 0 0.6 1" contype="0" conaffinity="0"/>
    <inertial pos="0 0 0" mass="1e-12" diaginertia="1e-12 1e-12 1e-12"/>
</body>
<body name="target7" pos="0 -0.5 1.1">
    <joint name="target7_free" type="free" damping="0"/>
    <geom type="sphere" size="0.02" rgba="1 1 0 1" contype="0" conaffinity="0"/>
    <inertial pos="0 0 0" mass="1e-12" diaginertia="1e-12 1e-12 1e-12"/>
</body>

<!-- CABLE/ROPE OBJECT -->
<body name="rope_root" pos="-0.94 0 0.845">
  <joint type="free" damping="0.1"/>
    <geom 
      type="capsule"
      fromto="0 0 0 0.0459 0 0"
      size="0.012"
      rgba="0 0 1 1"
      mass="0.0005"
      friction="100 100 0.01"
      solref="0.0001 1"
      solimp="0.999 0.999 0.001"
      condim="6"
    />
  <body name="rope_seg1" pos="0.0459 0 0">
    <joint type="ball" damping="0.07"/>
    <geom type="capsule" fromto="0 0 0 0.0459 0 0" size="0.012" rgba="0 0 1 1" mass="0.0001"/>
    <body name="rope_seg2" pos="0.0459 0 0">
      <joint type="ball" damping="0.07" stiffness="0"/>
      <geom type="capsule" fromto="0 0 0 0.0459 0 0" size="0.012" rgba="0 0 1 1" mass="0.0001"/>
      <body name="rope_seg3" pos="0.0459 0 0">
        <joint type="ball" damping="0.07" stiffness="0"/>
        <geom type="capsule" fromto="0 0 0 0.0459 0 0" size="0.012" rgba="0 0 1 1" mass="0.0001"/>
        <body name="rope_seg4" pos="0.0459 0 0">
          <joint type="ball" damping="0.07" stiffness="0"/>
          <geom type="capsule" fromto="0 0 0 0.0459 0 0" size="0.012" rgba="0 0 1 1" mass="0.0001"/>
          <body name="rope_seg5" pos="0.0459 0 0">
            <joint type="ball" damping="0.07" stiffness="0"/>
            <geom type="capsule" fromto="0 0 0 0.0459 0 0" size="0.012" rgba="0 0 1 1" mass="0.0001"/>
            <body name="rope_seg6" pos="0.0459 0 0">
              <joint type="ball" damping="0.07" stiffness="0"/>
              <geom type="capsule" fromto="0 0 0 0.0459 0 0" size="0.012" rgba="0 0 1 1" mass="0.0001"/>
              <body name="rope_seg7" pos="0.0459 0 0">
                <joint type="ball" damping="0.07" stiffness="0"/>
                <geom type="capsule" fromto="0 0 0 0.0459 0 0" size="0.012" rgba="0 0 1 1" mass="0.0001"/>
                <body name="rope_seg8" pos="0.0459 0 0">
                  <joint type="ball" damping="0.07" stiffness="0"/>
                  <geom type="capsule" fromto="0 0 0 0.0459 0 0" size="0.012" rgba="0 0 1 1" mass="0.0001"/>
                  <body name="rope_seg9" pos="0.0459 0 0">
                    <joint type="ball" damping="0.07" stiffness="0"/>
                    <geom type="capsule" fromto="0 0 0 0.0459 0 0" size="0.012" rgba="0 0 1 1" mass="0.0001"/>
                    <body name="rope_seg10" pos="0.0459 0 0">
                      <joint type="ball" damping="0.07" stiffness="0"/>
                      <geom type="capsule" fromto="0 0 0 0.0459 0 0" size="0.012" rgba="1 0 0 1" mass="0.0001"/>
                      <body name="rope_seg11" pos="0.0459 0 0">
                        <joint type="ball" damping="0.07" stiffness="0"/>
                        <geom type="capsule" fromto="0 0 0 0.0459 0 0" size="0.012" rgba="0 0 1 1" mass="0.0001"/>
                        <body name="rope_seg12" pos="0.0459 0 0">
                          <joint type="ball" damping="0.07" stiffness="0"/>
                          <geom type="capsule" fromto="0 0 0 0.0459 0 0" size="0.012" rgba="0 0 1 1" mass="0.0001"/>
                          <body name="rope_seg13" pos="0.0459 0 0">
                            <joint type="ball" damping="0.07" stiffness="0"/>
                            <geom type="capsule" fromto="0 0 0 0.0459 0 0" size="0.012" rgba="0 0 1 1" mass="0.0001"/>
                            <body name="rope_seg14" pos="0.0459 0 0">
                              <joint type="ball" damping="0.07" stiffness="0"/>
                              <geom type="capsule" fromto="0 0 0 0.0459 0 0" size="0.012" rgba="0 0 1 1" mass="0.0001"/>
                              <body name="rope_seg15" pos="0.0459 0 0">
                                <joint type="ball" damping="0.07" stiffness="0"/>
                                <geom type="capsule" fromto="0 0 0 0.0459 0 0" size="0.012" rgba="0 0 1 1" mass="0.0001"/>
                                <body name="rope_seg16" pos="0.0459 0 0">
                                  <joint type="ball" damping="0.07" stiffness="0"/>
                                  <geom type="capsule" fromto="0 0 0 0.0459 0 0" size="0.012" rgba="0 1 0 1" mass="0.0001"/>
                                  <body name="rope_seg17" pos="0.0459 0 0">
                                    <joint type="ball" damping="0.07" stiffness="0"/>
                                    <geom type="capsule" fromto="0 0 0 0.0459 0 0" size="0.012" rgba="0 0 1 1" mass="0.0001"/>
                                    <body name="rope_seg18" pos="0.0459 0 0">
                                      <joint type="ball" damping="0.07" stiffness="0"/>
                                      <geom type="capsule" fromto="0 0 0 0.0459 0 0" size="0.012" rgba="0 0 1 1" mass="0.0001"/>
                                      <body name="rope_seg19" pos="0.0459 0 0">
                                        <joint type="ball" damping="0.07" stiffness="0"/>
                                        <geom type="capsule" fromto="0 0 0 0.0459 0 0" size="0.012" rgba="0 0 1 1" mass="0.0001"/>
                                        <body name="rope_seg20" pos="0.0459 0 0">
                                          <joint type="ball" damping="0.07" stiffness="0"/>
                                          <geom type="capsule" fromto="0 0 0 0.0459 0 0" size="0.012" rgba="0 0 1 1" mass="0.0001"/>
                                          <body name="rope_seg21" pos="0.0459 0 0">
                                            <joint type="ball" damping="0.07" stiffness="0"/>
                                            <geom type="capsule" fromto="0 0 0 0.0459 0 0" size="0.012" rgba="0 0 1 1" mass="0.0001"/>
                                            <body name="rope_seg22" pos="0.0459 0 0">
                                              <joint type="ball" damping="0.07" stiffness="0"/>
                                              <geom type="capsule" fromto="0 0 0 0.0459 0 0" size="0.012" rgba="0 0 1 1" mass="0.0001"/>
                                              <body name="rope_seg23" pos="0.0459 0 0">
                                                <joint type="ball" damping="0.07" stiffness="0"/>
                                                <geom type="capsule" fromto="0 0 0 0.0459 0 0" size="0.012" rgba="0 0 1 1" mass="0.0005"/>
                                                <body name="rope_seg24" pos="0.0459 0 0">
                                                  <joint type="ball" damping="0.07" stiffness="0"/>
                                                  <geom type="capsule" fromto="0 0 0 0.0459 0 0" size="0.012" rgba="0.6 0 0.6 1" mass="0.0005"/>
                                                  <body name="rope_seg25" pos="0.0459 0 0">
                                                    <joint type="ball" damping="0.07" stiffness="0"/>
                                                    <geom type="capsule" fromto="0 0 0 0.0459 0 0" size="0.012" rgba="0 0 1 1" mass="0.0005"/>
                                                    <body name="rope_seg26" pos="0.0459 0 0">
                                                      <joint type="ball" damping="0.07" stiffness="0"/>
                                                      <geom type="capsule" fromto="0 0 0 0.0459 0 0" size="0.012" rgba="0 0 1 1" mass="0.0005"/>
                                                      <body name="rope_seg27" pos="0.0459 0 0">
                                                        <joint type="ball" damping="0.07" stiffness="0"/>
                                                        <geom type="capsule" fromto="0 0 0 0.0459 0 0" size="0.012" rgba="0 0 1 1" mass="0.0005"/>
                                                        <body name="rope_seg28" pos="0.0459 0 0">
                                                          <joint type="ball" damping="0.07" stiffness="0"/>
                                                          <geom type="capsule" fromto="0 0 0 0.0459 0 0" size="0.012" rgba="0 0 1 1" mass="0.0005"/>
                                                          <body name="rope_seg29" pos="0.0459 0 0">
                                                            <joint type="ball" damping="0.07" stiffness="0"/>
                                                            <geom type="capsule" fromto="0 0 0 0.0459 0 0" size="0.012" rgba="0 0 1 1" mass="0.0005"/>
                                                            <body name="rope_seg30" pos="0.0459 0 0">
                                                              <joint type="ball" damping="0.07" stiffness="0"/>
                                                              <geom type="capsule" fromto="0 0 0 0.0459 0 0" size="0.012" rgba="1 1 0 1" mass="0.0005"/>
                                                              <body name="rope_seg31" pos="0.0459 0 0">
                                                                <joint type="ball" damping="0.07" stiffness="0"/>
                                                                <geom type="capsule" fromto="0 0 0 0.0459 0 0" size="0.012" rgba="0 0 1 1" mass="0.0005"/>
                                                                <body name="rope_seg32" pos="0.0459 0 0">
                                                                  <joint type="ball" damping="0.07" stiffness="0"/>
                                                                  <geom type="capsule" fromto="0 0 0 0.0459 0 0" size="0.012" rgba="0 0 1 1" mass="0.0005"/>
                                                                  <body name="rope_seg33" pos="0.0459 0 0">
                                                                    <joint type="ball" damping="0.07" stiffness="0"/>
                                                                    <geom type="capsule" fromto="0 0 0 0.0459 0 0" size="0.012" rgba="0 0 1 1" mass="0.0005"/>
                                                                    <body name="rope_seg34" pos="0.0459 0 0">
                                                                      <joint type="ball" damping="0.07" stiffness="0"/>
                                                                      <geom type="capsule" fromto="0 0 0 0.0459 0 0" size="0.012" rgba="0 0 1 1" mass="0.0005"/>
                                                                      <body name="rope_seg35" pos="0.0459 0 0">
                                                                        <joint type="ball" damping="0.07" stiffness="0"/>
                                                                        <geom type="capsule" fromto="0 0 0 0.0459 0 0" size="0.012" rgba="0 0 1 1" mass="0.0005"/>
                                                                        <body name="rope_seg36" pos="0.0459 0 0">
                                                                          <joint type="ball" damping="0.07" stiffness="0"/>
                                                                          <geom type="capsule" fromto="0 0 0 0.0459 0 0" size="0.012" rgba="0 0 1 1" mass="0.0005"/>
                                                                          <body name="rope_seg37" pos="0.0459 0 0">
                                                                            <joint type="ball" damping="0.07" stiffness="0"/>
                                                                            <geom type="capsule" fromto="0 0 0 0.0459 0 0" size="0.012" rgba="0 0 1 1" mass="0.0005"/>
                                                                            <body name="rope_seg38" pos="0.0459 0 0">
                                                                              <joint type="ball" damping="0.07" stiffness="0"/>
                                                                              <geom type="capsule" fromto="0 0 0 0.0459 0 0" size="0.012" rgba="0 0 1 1" mass="0.0005"/>
                                                                              <body name="rope_seg39" pos="0.0459 0 0">
                                                                                <joint type="ball" damping="0.07" stiffness="0"/>
                                                                                <geom type="capsule" fromto="0 0 0 0.0459 0 0" size="0.012" rgba="0 0 1 1" mass="0.0005"/>
                                                                                <body name="rope_seg395" pos="0.0459 0 0">
                                                                                <joint type="ball" damping="0.07" stiffness="0"/>
                                                                                <geom type="capsule" fromto="0 0 0 0.0459 0 0" size="0.012" rgba="0 0 1 1" mass="0.0005"/>
                                                                                <body name="rope_seg40" pos="0.0459 0 0"> <!--0.0459 -->
                                                                                  <joint type="ball" damping="0.07" stiffness="0"/>
                                                                                <geom 
                                                                                  type="capsule"
                                                                                  fromto="0 0 0 0.0459 0 0"
                                                                                  size="0.02"
                                                                                  rgba="0 0 1 1"
                                                                                  mass="0.0005"
                                                                                  friction="100 100 0.01"
                                                                                  solref="0.0001 1"
                                                                                  solimp="0.999 0.999 0.001"
                                                                                  condim="6"
                                                                                />
                                                                                    </body>
                                                                                </body>
                                                                              </body>
                                                                            </body>
                                                                          </body>
                                                                        </body>
                                                                      </body>
                                                                    </body>
                                                                  </body>
                                                                </body>
                                                              </body>
                                                            </body>
                                                          </body>
                                                        </body>
                                                      </body>
                                                    </body>
                                                  </body>
                                                </body>
                                              </body>
                                            </body>
                                          </body>
                                        </body>
                                      </body>
                                    </body>
                                  </body>
                                </body>
                              </body>
                            </body>
                          </body>
                        </body>
                      </body>
                    </body>
                  </body>
                </body>
              </body>
            </body>
          </body>
        </body>
      </body>
    </body>
  </body>
</body>

<!-- SCENE BODY -->    
<light pos="0 0 1.5" dir="0 0 -1" directional="true"/>
<geom name="floor" size="0 0 0.05" type="plane" material="groundplane"/>

<!-- PANDA01 BODY -->
<light name="top_01" pos="0 0 2" mode="trackcom"/>
<body name="link0_01" childclass="panda_01" pos="1 0 0" quat="0 0 0 1">
  <inertial mass="0.629769" pos="-0.041018 -0.00014 0.049974"
    fullinertia="0.00315 0.00388 0.004285 8.2904e-7 0.00015 8.2299e-6"/>
  <geom mesh="link0_0_01" material="off_white_01" class="visual_01"/>
  <geom mesh="link0_1_01" material="black_01" class="visual_01"/>
  <geom mesh="link0_2_01" material="off_white_01" class="visual_01"/>
  <geom mesh="link0_3_01" material="black_01" class="visual_01"/>
  <geom mesh="link0_4_01" material="off_white_01" class="visual_01"/>
  <geom mesh="link0_5_01" material="black_01" class="visual_01"/>
  <geom mesh="link0_7_01" material="white_01" class="visual_01"/>
  <geom mesh="link0_8_01" material="white_01" class="visual_01"/>
  <geom mesh="link0_9_01" material="black_01" class="visual_01"/>
  <geom mesh="link0_10_01" material="off_white_01" class="visual_01"/>
  <geom mesh="link0_11_01" material="white_01" class="visual_01"/>
  <geom mesh="link0_c_01" class="collision_01"/>
  <body name="link1_01" pos="0 0 0.333">
    <inertial mass="4.970684" pos="0.003875 0.002081 -0.04762"
      fullinertia="0.70337 0.70661 0.0091170 -0.00013900 0.0067720 0.019169"/>
    <joint name="joint1_01"/>
    <geom material="white_01" mesh="link1_01" class="visual_01"/>
    <geom mesh="link1_c_01" class="collision_01"/>
    <body name="link2_01" quat="1 -1 0 0">
      <inertial mass="0.646926" pos="-0.003141 -0.02872 0.003495"
        fullinertia="0.0079620 2.8110e-2 2.5995e-2 -3.925e-3 1.0254e-2 7.04e-4"/>
      <joint name="joint2_01" range="-1.7628 1.7628"/>
      <geom material="white_01" mesh="link2_01" class="visual_01"/>
      <geom mesh="link2_c_01" class="collision_01"/>
      <body name="link3_01" pos="0 -0.316 0" quat="1 1 0 0">
        <joint name="joint3_01"/>
        <inertial mass="3.228604" pos="2.7518e-2 3.9252e-2 -6.6502e-2"
          fullinertia="3.7242e-2 3.6155e-2 1.083e-2 -4.761e-3 -1.1396e-2 -1.2805e-2"/>
        <geom mesh="link3_0_01" material="white_01" class="visual_01"/>
        <geom mesh="link3_1_01" material="white_01" class="visual_01"/>
        <geom mesh="link3_2_01" material="white_01" class="visual_01"/>
        <geom mesh="link3_3_01" material="black_01" class="visual_01"/>
        <geom mesh="link3_c_01" class="collision_01"/>
        <body name="link4_01" pos="0.0825 0 0" quat="1 1 0 0">
          <inertial mass="3.587895" pos="-5.317e-2 1.04419e-1 2.7454e-2"
            fullinertia="2.5853e-2 1.9552e-2 2.8323e-2 7.796e-3 -1.332e-3 8.641e-3"/>
          <joint name="joint4_01" range="-3.0718 -0.0698"/>
          <geom mesh="link4_0_01" material="white_01" class="visual_01"/>
          <geom mesh="link4_1_01" material="white_01" class="visual_01"/>
          <geom mesh="link4_2_01" material="black_01" class="visual_01"/>
          <geom mesh="link4_3_01" material="white_01" class="visual_01"/>
          <geom mesh="link4_c_01" class="collision_01"/>
          <body name="link5_01" pos="-0.0825 0.384 0" quat="1 -1 0 0">
            <inertial mass="1.225946" pos="-1.1953e-2 4.1065e-2 -3.8437e-2"
              fullinertia="3.5549e-2 2.9474e-2 8.627e-3 -2.117e-3 -4.037e-3 2.29e-4"/>
            <joint name="joint5_01"/>
            <geom mesh="link5_0_01" material="black_01" class="visual_01"/>
            <geom mesh="link5_1_01" material="white_01" class="visual_01"/>
            <geom mesh="link5_2_01" material="white_01" class="visual_01"/>
            <geom mesh="link5_c0_01" class="collision_01"/>
            <geom mesh="link5_c1_01" class="collision_01"/>
            <geom mesh="link5_c2_01" class="collision_01"/>
            <body name="link6_01" quat="1 1 0 0">
              <inertial mass="1.666555" pos="6.0149e-2 -1.4117e-2 -1.0517e-2"
                fullinertia="1.964e-3 4.354e-3 5.433e-3 1.09e-4 -1.158e-3 3.41e-4"/>
              <joint name="joint6_01" range="-0.0175 3.7525"/>
              <geom mesh="link6_0_01" material="off_white_01" class="visual_01"/>
              <geom mesh="link6_1_01" material="white_01" class="visual_01"/>
              <geom mesh="link6_2_01" material="black_01" class="visual_01"/>
              <geom mesh="link6_3_01" material="white_01" class="visual_01"/>
              <geom mesh="link6_4_01" material="white_01" class="visual_01"/>
              <geom mesh="link6_5_01" material="white_01" class="visual_01"/>
              <geom mesh="link6_6_01" material="white_01" class="visual_01"/>
              <geom mesh="link6_6_01" material="white_01" class="visual_01"/>
              <geom mesh="link6_7_01" material="light_blue_01" class="visual_01"/>
              <geom mesh="link6_8_01" material="light_blue_01" class="visual_01"/>
              <geom mesh="link6_9_01" material="black_01" class="visual_01"/>
              <geom mesh="link6_10_01" material="black_01" class="visual_01"/>
              <geom mesh="link6_11_01" material="white_01" class="visual_01"/>
              <geom mesh="link6_12_01" material="green_01" class="visual_01"/>
              <geom mesh="link6_13_01" material="white_01" class="visual_01"/>
              <geom mesh="link6_14_01" material="black_01" class="visual_01"/>
              <geom mesh="link6_15_01" material="black_01" class="visual_01"/>
              <geom mesh="link6_16_01" material="white_01" class="visual_01"/>
              <geom mesh="link6_c_01" class="collision_01"/>
              <body name="link7_01" pos="0.088 0 0" quat="1 1 0 0">
                <inertial mass="7.35522e-01" pos="1.0517e-2 -4.252e-3 6.1597e-2"
                  fullinertia="1.2516e-2 1.0027e-2 4.815e-3 -4.28e-4 -1.196e-3 -7.41e-4"/>
                <joint name="joint7_01"/>
                <geom mesh="link7_0_01" material="white_01" class="visual_01"/>
                <geom mesh="link7_1_01" material="black_01" class="visual_01"/>
                <geom mesh="link7_2_01" material="black_01" class="visual_01"/>
                <geom mesh="link7_3_01" material="black_01" class="visual_01"/>
                <geom mesh="link7_4_01" material="black_01" class="visual_01"/>
                <geom mesh="link7_5_01" material="black_01" class="visual_01"/>
                <geom mesh="link7_6_01" material="black_01" class="visual_01"/>
                <geom mesh="link7_7_01" material="white_01" class="visual_01"/>
                <geom mesh="link7_c_01" class="collision_01"/>
                <body name="hand_1_01" pos="0 0 0.107" quat="0 0 0 1">
                                  
                  <inertial mass="0.73" pos="-0.01 0 0.03" diaginertia="0.001 0.0025 0.0017"/>
                  <geom mesh="hand_0_01" material="off_white_01" class="visual_01"/>
                  <geom mesh="hand_1_01" material="black_01" class="visual_01"/>
                  <geom mesh="hand_2_01" material="black_01" class="visual_01"/>
                  <geom mesh="hand_3_01" material="white_01" class="visual_01"/>
                  <geom mesh="hand_4_01" material="off_white_01" class="visual_01"/>
                  <geom mesh="hand_c_01" class="collision_01"/>
                    
                  <body name="left_finger_01" pos="0 0 0.0584">
                    <inertial mass="0.015" pos="0 0 0" diaginertia="2.375e-6 2.375e-6 7.5e-7"/>
                    <joint name="finger_joint1_01" class="finger_01"/>
                    <geom mesh="finger_0_01" material="off_white_01" class="visual_01"/>
                    <geom mesh="finger_1_01" material="black_01" class="visual_01"/>
                    <geom mesh="finger_0_01" class="collision_01"/>
                    <geom class="fingertip_pad_collision_1_01" friction="100 100 0.01" condim="6" solref="0.0001 1" solimp="0.999 0.999 0.001"/>
                    <geom class="fingertip_pad_collision_2_01" friction="100 100 0.01" condim="6" solref="0.0001 1" solimp="0.999 0.999 0.001"/>
                    <geom class="fingertip_pad_collision_3_01" friction="100 100 0.01" condim="6" solref="0.0001 1" solimp="0.999 0.999 0.001"/>
                    <geom class="fingertip_pad_collision_4_01" friction="100 100 0.01" condim="6" solref="0.0001 1" solimp="0.999 0.999 0.001"/>
                    <geom class="fingertip_pad_collision_5_01" friction="100 100 0.01" condim="6" solref="0.0001 1" solimp="0.999 0.999 0.001"/>
                  </body>
                    
                  <body name="right_finger_01" pos="0 0 0.0584" quat="0 0 0 1">
                    <inertial mass="0.015" pos="0 0 0" diaginertia="2.375e-6 2.375e-6 7.5e-7"/>
                    <joint name="finger_joint2_01" class="finger_01"/>
                    <geom mesh="finger_0_01" material="off_white_01" class="visual_01"/>
                    <geom mesh="finger_1_01" material="black_01" class="visual_01"/>
                    <geom mesh="finger_0_01" class="collision_01"/>
                    <geom class="fingertip_pad_collision_1_01" friction="100 100 0.01" condim="6" solref="0.0001 1" solimp="0.999 0.999 0.001"/>
                    <geom class="fingertip_pad_collision_2_01" friction="100 100 0.01" condim="6" solref="0.0001 1" solimp="0.999 0.999 0.001"/>
                    <geom class="fingertip_pad_collision_3_01" friction="100 100 0.01" condim="6" solref="0.0001 1" solimp="0.999 0.999 0.001"/>
                    <geom class="fingertip_pad_collision_4_01" friction="100 100 0.01" condim="6" solref="0.0001 1" solimp="0.999 0.999 0.001"/>
                    <geom class="fingertip_pad_collision_5_01" friction="100 100 0.01" condim="6" solref="0.0001 1" solimp="0.999 0.999 0.001"/>
                  </body>
                </body>
              </body>
            </body>
          </body>
        </body>
      </body>
    </body>
  </body>
</body>

<!-- PANDA02 BODY -->
<light name="top_02" pos="0 0 2" mode="trackcom"/>
<body name="link0_02" childclass="panda_02" pos="-1 0 0" quat="1 0 0 0">
      <inertial mass="0.629769" pos="-0.041018 -0.00014 0.049974"
        fullinertia="0.00315 0.00388 0.004285 8.2904e-7 0.00015 8.2299e-6"/>
      <geom mesh="link0_0_02" material="off_white_02" class="visual_02"/>
      <geom mesh="link0_1_02" material="black_02" class="visual_02"/>
      <geom mesh="link0_2_02" material="off_white_02" class="visual_02"/>
      <geom mesh="link0_3_02" material="black_02" class="visual_02"/>
      <geom mesh="link0_4_02" material="off_white_02" class="visual_02"/>
      <geom mesh="link0_5_02" material="black_02" class="visual_02"/>
      <geom mesh="link0_7_02" material="white_02" class="visual_02"/>
      <geom mesh="link0_8_02" material="white_02" class="visual_02"/>
      <geom mesh="link0_9_02" material="black_02" class="visual_02"/>
      <geom mesh="link0_10_02" material="off_white_02" class="visual_02"/>
      <geom mesh="link0_11_02" material="white_02" class="visual_02"/>
      <geom mesh="link0_c_02" class="collision_02"/>
      <body name="link1_02" pos="0 0 0.333">
        <inertial mass="4.970684" pos="0.003875 0.002081 -0.04762"
          fullinertia="0.70337 0.70661 0.0091170 -0.00013900 0.0067720 0.019169"/>
        <joint name="joint1_02"/>
        <geom material="white_02" mesh="link1_02" class="visual_02"/>
        <geom mesh="link1_c_02" class="collision_02"/>
        <body name="link2_02" quat="1 -1 0 0">
          <inertial mass="0.646926" pos="-0.003141 -0.02872 0.003495"
            fullinertia="0.0079620 2.8110e-2 2.5995e-2 -3.925e-3 1.0254e-2 7.04e-4"/>
          <joint name="joint2_02" range="-1.7628 1.7628"/>
          <geom material="white_02" mesh="link2_02" class="visual_02"/>
          <geom mesh="link2_c_02" class="collision_02"/>
          <body name="link3_02" pos="0 -0.316 0" quat="1 1 0 0">
            <joint name="joint3_02"/>
            <inertial mass="3.228604" pos="2.7518e-2 3.9252e-2 -6.6502e-2"
              fullinertia="3.7242e-2 3.6155e-2 1.083e-2 -4.761e-3 -1.1396e-2 -1.2805e-2"/>
            <geom mesh="link3_0_02" material="white_02" class="visual_02"/>
            <geom mesh="link3_1_02" material="white_02" class="visual_02"/>
            <geom mesh="link3_2_02" material="white_02" class="visual_02"/>
            <geom mesh="link3_3_02" material="black_02" class="visual_02"/>
            <geom mesh="link3_c_02" class="collision_02"/>
            <body name="link4_02" pos="0.0825 0 0" quat="1 1 0 0">
              <inertial mass="3.587895" pos="-5.317e-2 1.04419e-1 2.7454e-2"
                fullinertia="2.5853e-2 1.9552e-2 2.8323e-2 7.796e-3 -1.332e-3 8.641e-3"/>
              <joint name="joint4_02" range="-3.0718 -0.0698"/>
              <geom mesh="link4_0_02" material="white_02" class="visual_02"/>
              <geom mesh="link4_1_02" material="white_02" class="visual_02"/>
              <geom mesh="link4_2_02" material="black_02" class="visual_02"/>
              <geom mesh="link4_3_02" material="white_02" class="visual_02"/>
              <geom mesh="link4_c_02" class="collision_02"/>
              <body name="link5_02" pos="-0.0825 0.384 0" quat="1 -1 0 0">
                <inertial mass="1.225946" pos="-1.1953e-2 4.1065e-2 -3.8437e-2"
                  fullinertia="3.5549e-2 2.9474e-2 8.627e-3 -2.117e-3 -4.037e-3 2.29e-4"/>
                <joint name="joint5_02"/>
                <geom mesh="link5_0_02" material="black_02" class="visual_02"/>
                <geom mesh="link5_1_02" material="white_02" class="visual_02"/>
                <geom mesh="link5_2_02" material="white_02" class="visual_02"/>
                <geom mesh="link5_c0_02" class="collision_02"/>
                <geom mesh="link5_c1_02" class="collision_02"/>
                <geom mesh="link5_c2_02" class="collision_02"/>
                  
                <body name="link6_02" quat="1 1 0 0">
                  <inertial mass="1.666555" pos="6.0149e-2 -1.4117e-2 -1.0517e-2"
                    fullinertia="1.964e-3 4.354e-3 5.433e-3 1.09e-4 -1.158e-3 3.41e-4"/>
                  <joint name="joint6_02" range="-0.0175 3.7525"/>
                  <geom mesh="link6_0_02" material="off_white_02" class="visual_02"/>
                  <geom mesh="link6_1_02" material="white_02" class="visual_02"/>
                  <geom mesh="link6_2_02" material="black_02" class="visual_02"/>
                  <geom mesh="link6_3_02" material="white_02" class="visual_02"/>
                  <geom mesh="link6_4_02" material="white_02" class="visual_02"/>
                  <geom mesh="link6_5_02" material="white_02" class="visual_02"/>
                  <geom mesh="link6_6_02" material="white_02" class="visual_02"/>
                  <geom mesh="link6_6_02" material="white_02" class="visual_02"/>
                    
                  <geom mesh="link6_7_02" material="light_blue_02" class="visual_02"/>
 
                  <geom mesh="link6_8_02" material="light_blue_02" class="visual_02"/>
                  <geom mesh="link6_9_02" material="black_02" class="visual_02"/>
                  <geom mesh="link6_10_02" material="black_02" class="visual_02"/>
                  <geom mesh="link6_11_02" material="white_02" class="visual_02"/>
                    
                  <geom mesh="link6_12_02" material="green_02" class="visual_02"/>
                    
                  <geom mesh="link6_13_02" material="white_02" class="visual_02"/>
                  <geom mesh="link6_14_02" material="black_02" class="visual_02"/>
                  <geom mesh="link6_15_02" material="black_02" class="visual_02"/>
                  <geom mesh="link6_16_02" material="white_02" class="visual_02"/>
                  <geom mesh="link6_c_02" class="collision_02"/>
                    
                  <body name="link7_02" pos="0.088 0 0" quat="1 1 0 0">
                    <inertial mass="7.35522e-01" pos="1.0517e-2 -4.252e-3 6.1597e-2"
                      fullinertia="1.2516e-2 1.0027e-2 4.815e-3 -4.28e-4 -1.196e-3 -7.41e-4"/>
                    <joint name="joint7_02"/>
                    <geom mesh="link7_0_02" material="white_02" class="visual_02"/>
                    <geom mesh="link7_1_02" material="black_02" class="visual_02"/>
                    <geom mesh="link7_2_02" material="black_02" class="visual_02"/>
                    <geom mesh="link7_3_02" material="black_02" class="visual_02"/>
                    <geom mesh="link7_4_02" material="black_02" class="visual_02"/>
                    <geom mesh="link7_5_02" material="black_02" class="visual_02"/>
                    <geom mesh="link7_6_02" material="black_02" class="visual_02"/>
                    <geom mesh="link7_7_02" material="white_02" class="visual_02"/>
                    <geom mesh="link7_c_02" class="collision_02"/>
                      
                    <body name="hand_1_02" pos="0 0 0.107" quat="0 0 0 -1">                        
                        <inertial mass="0.73" pos="-0.01 0 0.03" diaginertia="0.001 0.0025 0.0017"/>
                      <geom mesh="hand_0_02" material="off_white_02" class="visual_02"/>
                      <geom mesh="hand_1_02" material="black_02" class="visual_02"/>
                      <geom mesh="hand_2_02" material="black_02" class="visual_02"/>
                      <geom mesh="hand_3_02" material="white_02" class="visual_02"/>
                      <geom mesh="hand_4_02" material="off_white_02" class="visual_02"/>
                      <geom mesh="hand_c_02" class="collision_02"/>
                        <body name="left_finger_02" pos="0 0 0.0584">
                        <inertial mass="0.015" pos="0 0 0" diaginertia="2.375e-6 2.375e-6 7.5e-7"/>
                        <joint name="finger_joint1_02" class="finger_02"/>
                        <geom mesh="finger_0_02" material="off_white_02" class="visual_02"/>
                        <geom mesh="finger_1_02" material="black_02" class="visual_02"/>
                        <geom mesh="finger_0_02" class="collision_02"/>
                        <geom class="fingertip_pad_collision_1_02" friction="100 100 0.01" condim="6" solref="0.0001 1" solimp="0.999 0.999 0.001"/>
                        <geom class="fingertip_pad_collision_2_02" friction="100 100 0.01" condim="6" solref="0.0001 1" solimp="0.999 0.999 0.001"/>
                        <geom class="fingertip_pad_collision_3_02" friction="100 100 0.01" condim="6" solref="0.0001 1" solimp="0.999 0.999 0.001"/>
                        <geom class="fingertip_pad_collision_4_02" friction="100 100 0.01" condim="6" solref="0.0001 1" solimp="0.999 0.999 0.001"/>
                        <geom class="fingertip_pad_collision_5_02" friction="100 100 0.01" condim="6" solref="0.0001 1" solimp="0.999 0.999 0.001"/>
                        </body>
                        
                      <body name="right_finger_02" pos="0 0 0.0584" quat="0 0 0 1">
                        <inertial mass="0.015" pos="0 0 0" diaginertia="2.375e-6 2.375e-6 7.5e-7"/>
                        <joint name="finger_joint2_02" class="finger_02"/>
                        <geom mesh="finger_0_02" material="off_white_02" class="visual_02"/>
                        <geom mesh="finger_1_02" material="black_02" class="visual_02"/>
                        <geom mesh="finger_0_02" class="collision_02"/>
                        <geom class="fingertip_pad_collision_1_02" friction="100 100 0.01" condim="6" solref="0.0001 1" solimp="0.999 0.999 0.001"/>
                        <geom class="fingertip_pad_collision_2_02" friction="100 100 0.01" condim="6" solref="0.0001 1" solimp="0.999 0.999 0.001"/>
                        <geom class="fingertip_pad_collision_3_02" friction="100 100 0.01" condim="6" solref="0.0001 1" solimp="0.999 0.999 0.001"/>
                        <geom class="fingertip_pad_collision_4_02" friction="100 100 0.01" condim="6" solref="0.0001 1" solimp="0.999 0.999 0.001"/>
                        <geom class="fingertip_pad_collision_5_02" friction="100 100 0.01" condim="6" solref="0.0001 1" solimp="0.999 0.999 0.001"/>
                      </body>                      
                    </body>
                  </body>
                </body>
              </body>
            </body>
          </body>
        </body>
      </body>
    </body>
</worldbody>

<!-- PANDA01 TENDON -->
<tendon>
    <fixed name="split_01">
        <joint joint="finger_joint1_01" coef="0.5"/>
        <joint joint="finger_joint2_01" coef="0.5"/>
    </fixed>
</tendon>

<!-- PANDA01 EQUALITY -->
<equality>
    <joint joint1="finger_joint1_01" joint2="finger_joint2_01" solimp="0.95 0.99 0.001" solref="0.005 1"/>
</equality>
    
<!-- PANDA01 ACTUATOR -->
<actuator>
    <general class="panda_01" name="actuator1_01" joint="joint1_01" gainprm="4500" biasprm="0 -4500 -450"/>
    <general class="panda_01" name="actuator2_01" joint="joint2_01" gainprm="4500" biasprm="0 -4500 -450"
    ctrlrange="-1.7628 1.7628"/>
    <general class="panda_01" name="actuator3_01" joint="joint3_01" gainprm="3500" biasprm="0 -3500 -350"/>
    <general class="panda_01" name="actuator4_01" joint="joint4_01" gainprm="3500" biasprm="0 -3500 -350"
    ctrlrange="-3.0718 -0.0698"/>
    <general class="panda_01" name="actuator5_01" joint="joint5_01" gainprm="2000" biasprm="0 -2000 -200" forcerange="-12 12"/>
    <general class="panda_01" name="actuator6_01" joint="joint6_01" gainprm="2000" biasprm="0 -2000 -200" forcerange="-12 12"
    ctrlrange="-0.0175 3.7525"/>
    <general class="panda_01" name="actuator7_01" joint="joint7_01" gainprm="2000" biasprm="0 -2000 -200" forcerange="-12 12"/>
    <!-- Remap original ctrlrange (0, 0.04) to (0, 255): 0.04 * 100 / 255 = 0.01568627451 -->
    <general class="panda_01" name="actuator8_01" tendon="split_01" forcerange="-100 100" ctrlrange="0 255"
    gainprm="0.01568627451 0 0" biasprm="0 -100 -10"/>
</actuator>

<!-- PANDA02 TENDON -->
<tendon>
    <fixed name="split_02">
        <joint joint="finger_joint1_02" coef="0.5"/>
        <joint joint="finger_joint2_02" coef="0.5"/>
    </fixed>
</tendon>

<!-- PANDA02 EQUALITY -->
<equality>
    <joint joint1="finger_joint1_02" joint2="finger_joint2_02" solimp="0.95 0.99 0.001" solref="0.005 1"/>
</equality>

<!-- PANDA02 ACTUATOR -->
<actuator>
    <general class="panda_02" name="actuator1_02" joint="joint1_02" gainprm="4500" biasprm="0 -4500 -450"/>
    <general class="panda_02" name="actuator2_02" joint="joint2_02" gainprm="4500" biasprm="0 -4500 -450"
    ctrlrange="-1.7628 1.7628"/>
    <general class="panda_02" name="actuator3_02" joint="joint3_02" gainprm="3500" biasprm="0 -3500 -350"/>
    <general class="panda_02" name="actuator4_02" joint="joint4_02" gainprm="3500" biasprm="0 -3500 -350"
    ctrlrange="-3.0718 -0.0698"/>
    <general class="panda_02" name="actuator5_02" joint="joint5_02" gainprm="2000" biasprm="0 -2000 -200" forcerange="-12 12"/>
    <general class="panda_02" name="actuator6_02" joint="joint6_02" gainprm="2000" biasprm="0 -2000 -200" forcerange="-12 12"
    ctrlrange="-0.0175 3.7525"/>
    <general class="panda_02" name="actuator7_02" joint="joint7_02" gainprm="2000" biasprm="0 -2000 -200" forcerange="-12 12"/>
    <!-- Remap original ctrlrange (0, 0.04) to (0, 255): 0.04 * 100 / 255 = 0.01568627451 -->
    <general class="panda_02" name="actuator8_02" tendon="split_02" forcerange="-100 100" ctrlrange="0 255"
    gainprm="0.01568627451 0 0" biasprm="0 -100 -10"/>
</actuator>

</mujoco>
